2025-07-10 16:50:17,529 - INFO - agents.agent_registry - Loaded agent configurations from agent_configs.json
2025-07-10 16:51:12,765 - INFO - mcp_bridge - [MCP_BRIDGE] Task ID: ae757bfc-fb9f-4893-8860-6cafd31a2262 | Agent: 'llama_summarization_agent' | Input: Sample PDF content
2025-07-10 16:51:13,254 - INFO - agents.stream_transformer_agent - Processing task with model: llama
2025-07-10 16:51:13,254 - ERROR - integration.llm_router - Model not supported: llama
2025-07-10 16:51:13,254 - INFO - agents.stream_transformer_agent - Task processed successfully: {'error': 'Model not supported', 'status': 400}
2025-07-10 16:51:13,255 - INFO - mcp_bridge - [MCP_BRIDGE] Task ID: ae757bfc-fb9f-4893-8860-6cafd31a2262 | Agent 'llama_summarization_agent' executed successfully.
2025-07-10 16:51:13,255 - ERROR - mcp_bridge - [MCP_BRIDGE] Task ID: ae757bfc-fb9f-4893-8860-6cafd31a2262 | Agent 'llama_summarization_agent' failed: 1 validation error for TaskResponse
agent_output
  Input should be a valid string [type=string_type, input_value={'error': 'Model not supported', 'status': 400}, input_type=dict]
    For further information visit https://errors.pydantic.dev/2.9/v/string_type
2025-07-10 16:53:29,632 - ERROR - __main__ - Error running CLI task: HTTPConnectionPool(host='localhost', port=8000): Max retries exceeded with url: /handle_task (Caused by NewConnectionError('<urllib3.connection.HTTPConnection object at 0x000001C1FE349A90>: Failed to establish a new connection: [WinError 10061] No connection could be made because the target machine actively refused it'))
2025-07-10 17:13:41,707 - INFO - agents.agent_registry - Loaded agent configurations from agent_configs.json
2025-07-10 17:14:05,643 - INFO - mcp_bridge - [MCP_BRIDGE] Task ID: afe01602-e740-4830-a33f-d32f23a61ab1 | Agent: 'llama_summarization_agent' | Input: Sample PDF content
2025-07-10 17:14:05,984 - INFO - agents.stream_transformer_agent - Processing task with model: llama
2025-07-10 17:14:05,984 - INFO - integration.llm_router - Running model: llama with query: Sample PDF content...
2025-07-10 17:14:10,058 - ERROR - integration.llm_router - Error running model llama: HTTPConnectionPool(host='localhost', port=1234): Max retries exceeded with url: /v1/chat/completions (Caused by NewConnectionError('<urllib3.connection.HTTPConnection object at 0x000001D88F2A6E40>: Failed to establish a new connection: [WinError 10061] No connection could be made because the target machine actively refused it'))
2025-07-10 17:14:10,058 - INFO - agents.stream_transformer_agent - Task processed successfully: {'error': "Model execution failed: HTTPConnectionPool(host='localhost', port=1234): Max retries exceeded with url: /v1/chat/completions (Caused by NewConnectionError('<urllib3.connection.HTTPConnection object at 0x000001D88F2A6E40>: Failed to establish a new connection: [WinError 10061] No connection could be made because the target machine actively refused it'))", 'status': 500}
2025-07-10 17:14:10,058 - INFO - mcp_bridge - [MCP_BRIDGE] Task ID: afe01602-e740-4830-a33f-d32f23a61ab1 | Agent 'llama_summarization_agent' executed successfully.
2025-07-10 17:14:10,059 - ERROR - mcp_bridge - [MCP_BRIDGE] Task ID: afe01602-e740-4830-a33f-d32f23a61ab1 | Agent 'llama_summarization_agent' failed: 1 validation error for TaskResponse
agent_output
  Input should be a valid string [type=string_type, input_value={'error': "Model executio...d it'))", 'status': 500}, input_type=dict]
    For further information visit https://errors.pydantic.dev/2.9/v/string_type
2025-07-10 17:16:21,819 - INFO - agents.agent_registry - Loaded agent configurations from agent_configs.json
2025-07-10 17:16:46,502 - INFO - mcp_bridge - [MCP_BRIDGE] Task ID: eaa16d95-5d50-4296-a17f-425f5c12ce83 | Agent: 'llama_summarization_agent' | Input: Sample PDF content
2025-07-10 17:16:46,800 - INFO - agents.stream_transformer_agent - Processing task with model: llama
2025-07-10 17:16:46,800 - INFO - integration.llm_router - Running model: llama with query: Sample PDF content...
2025-07-10 17:16:50,889 - ERROR - integration.llm_router - Error running model llama: HTTPConnectionPool(host='localhost', port=1234): Max retries exceeded with url: /v1/chat/completions (Caused by NewConnectionError('<urllib3.connection.HTTPConnection object at 0x0000029CA7B5ECF0>: Failed to establish a new connection: [WinError 10061] No connection could be made because the target machine actively refused it'))
2025-07-10 17:16:50,890 - INFO - agents.stream_transformer_agent - Task processed successfully: {'error': "Model execution failed: HTTPConnectionPool(host='localhost', port=1234): Max retries exceeded with url: /v1/chat/completions (Caused by NewConnectionError('<urllib3.connection.HTTPConnection object at 0x0000029CA7B5ECF0>: Failed to establish a new connection: [WinError 10061] No connection could be made because the target machine actively refused it'))", 'status': 500}
2025-07-10 17:16:50,890 - ERROR - mcp_bridge - [MCP_BRIDGE] Task ID: eaa16d95-5d50-4296-a17f-425f5c12ce83 | Agent 'llama_summarization_agent' failed: Model execution failed: HTTPConnectionPool(host='localhost', port=1234): Max retries exceeded with url: /v1/chat/completions (Caused by NewConnectionError('<urllib3.connection.HTTPConnection object at 0x0000029CA7B5ECF0>: Failed to establish a new connection: [WinError 10061] No connection could be made because the target machine actively refused it'))
2025-07-10 17:32:58,001 - ERROR - __main__ - Error running CLI task: HTTPConnectionPool(host='localhost', port=8000): Max retries exceeded with url: /handle_task (Caused by NewConnectionError('<urllib3.connection.HTTPConnection object at 0x000001B3838A9A90>: Failed to establish a new connection: [WinError 10061] No connection could be made because the target machine actively refused it'))
2025-07-10 17:34:11,453 - WARNING - __main__ - Attempt 1/3 failed: HTTPConnectionPool(host='localhost', port=8000): Max retries exceeded with url: /handle_task (Caused by NewConnectionError('<urllib3.connection.HTTPConnection object at 0x00000222436C9BE0>: Failed to establish a new connection: [WinError 10061] No connection could be made because the target machine actively refused it'))
2025-07-10 17:34:17,501 - WARNING - __main__ - Attempt 2/3 failed: HTTPConnectionPool(host='localhost', port=8000): Max retries exceeded with url: /handle_task (Caused by NewConnectionError('<urllib3.connection.HTTPConnection object at 0x00000222436F1D10>: Failed to establish a new connection: [WinError 10061] No connection could be made because the target machine actively refused it'))
2025-07-10 17:34:23,584 - WARNING - __main__ - Attempt 3/3 failed: HTTPConnectionPool(host='localhost', port=8000): Max retries exceeded with url: /handle_task (Caused by NewConnectionError('<urllib3.connection.HTTPConnection object at 0x00000222436F25D0>: Failed to establish a new connection: [WinError 10061] No connection could be made because the target machine actively refused it'))
2025-07-10 17:34:23,585 - ERROR - __main__ - Error running CLI task: HTTPConnectionPool(host='localhost', port=8000): Max retries exceeded with url: /handle_task (Caused by NewConnectionError('<urllib3.connection.HTTPConnection object at 0x00000222436F25D0>: Failed to establish a new connection: [WinError 10061] No connection could be made because the target machine actively refused it'))
